Workbook

Sheet Overzicht
A1: Overzicht – APA Activa Sunprojects BV, pagina 27–33
A2: Alle bedragen in euro. Groene cijfers zijn koppelingen naar de detailtabbladen; blauw = overgenomen uit de PDF.
A4: 1. Materiële vaste activa 2025
A5: Register | B5: Aanschafwaarde primo | C5: Boekwaarde primo | D5: Investering | E5: Afschrijving 2025 | F5: Aanschafwaarde ultimo | G5: Boekwaarde ultimo | H5: Pagina
A6: Machines en installaties | B6: ='Machines (p27)'!C37 -> 58472 | C6: ='Machines (p27)'!G37 -> 14804 | D6: ='Machines (p27)'!H37 -> 0 | E6: ='Machines (p27)'!I37 -> 7432 | F6: ='Machines (p27)'!J37 -> 58472 | G6: ='Machines (p27)'!L37 -> 7372 | H6: 27
A7: Kantoorinventaris | B7: ='Kantoorinventaris (p29)'!C23 -> 17963 | C7: ='Kantoorinventaris (p29)'!G23 -> 2880 | D7: ='Kantoorinventaris (p29)'!H23 -> 0 | E7: ='Kantoorinventaris (p29)'!K23 -> 1773 | F7: ='Kantoorinventaris (p29)'!L23 -> 8966 | G7: ='Kantoorinventaris (p29)'!N23 -> 907 | H7: 29
A8: Automatiseringsapparatuur | B8: ='Automatisering (p31)'!C37 -> 64624 | C8: ='Automatisering (p31)'!G37 -> 22122 | D8: ='Automatisering (p31)'!H37 -> 478 | E8: ='Automatisering (p31)'!I37 -> 6989 | F8: ='Automatisering (p31)'!J37 -> 65102 | G8: ='Automatisering (p31)'!L37 -> 13813 | H8: 31
A9: Totaal MVA | B9: =SUM(B6:B8) -> 141059 | C9: =SUM(C6:C8) -> 39806 | D9: =SUM(D6:D8) -> 478 | E9: =SUM(E6:E8) -> 16194 | F9: =SUM(F6:F8) -> 132540 | G9: =SUM(G6:G8) -> 22092
A10: Kantoorinventaris: aanschafwaarde ultimo is na desinvestering (verkoop aan illi Engineering, 20-08-2025).
A12: 2. Voorraad per eind Q4-2025 (p30)
A13: Loods Den Helder | B13: ='Voorraad (p30)'!G44 -> 98667.84
A14: Andere locaties (volgens PDF) | B14: ='Voorraad (p30)'!G61 -> 10810.1
A15: Totaal voorraad | B15: ='Voorraad (p30)'!G64 -> 109477.94
A16: Let op: het PDF-totaal voor andere locaties (€ 10.810,10) telt de container Eerbeek (€ 2.186,70) niet mee — zie tabblad Voorraad.
A18: 3. Auto's (p28)
A19: Aantal leaseauto's | B19: =COUNTA('Auto''s (p28)'!D5:D9) -> 5
A20: Leasebedrag per maand (totaal) | B20: ='Auto''s (p28)'!H10 -> 4150.32
A21: Afkoopindicatie per 31-12-2025 ex btw (totaal) | B21: ='Auto''s (p28)'!A10 -> 125682.22
A22: Eigen auto Volvo XC90 (aankoopprijs 08-01-2023) | B22: ='Auto''s (p28)'!A14 -> 43949.99
A24: 4. Personeel – begroting 2026 (p32)
A25: Aantal werknemers | B25: ='Personeel (p32)'!Q28 -> 15
A26: Aantal FTE | B26: ='Personeel (p32)'!Q27 -> 11.341666
A27: Totaal salaris en sociale lasten 2026 | B27: ='Personeel (p32)'!Q25 -> 859776
A28: Vorige begroting 2026 (november) | B28: ='Personeel (p32)'!Q26 -> 1182329
A29: Verschil t.o.v. vorige begroting | B29: =B27-B28 -> -322553
A31: 5. Contracten en pipeline (p33, stand 14-4-2026)
B32: Contract value | C32: Margin | D32: Margin %
A33: Signed contracts (7) | B33: ='Contracten (p33)'!B13 -> 14932340 | C33: ='Contracten (p33)'!C13 -> 2510906 | D33: =IF(B33=0,0,C33/B33) -> 0.16815221
A34: In negotiation | B34: ='Contracten (p33)'!B18 -> 236000 | C34: ='Contracten (p33)'!C18 -> 50000 | D34: =IF(B34=0,0,C34/B34) -> 0.21186441
A35: Aantal pipelineprojecten | B35: =COUNTA('Contracten (p33)'!A28:A40) -> 13

Sheet Machines (p27)
A1: Afschrijvingsstaat machines en installaties 2025 – Sunprojects BV
A2: Bron: APA Activa Sunprojects (getekend door beiden), pagina 27 — afschrijving 20% per jaar
A4: Omschrijving | B4: Aanschafdatum | C4: Aanschafwaarde primo | D4: Aantal mnd afschr. | E4: Afschr. % | F4: Cum. afschr. primo | G4: Boekwaarde primo | H4: Investering | I4: Afschrijving W&V 2025 | J4: Aanschafwaarde ultimo | K4: Cum. afschr. ultimo | L4: Boekwaarde ultimo | M4: Restwaarde | N4: Locatie / bij wie | O4: Opmerking
A5: Thermografische warmtebeeld camera Nardo | B5: 03-10-17 | C5: 894 | D5: 0 | E5: 0.2 | F5: 894 | G5: 0 | I5: 0 | J5: =C5+H5 -> 894 | K5: =F5+I5 -> 894 | L5: =J5-K5 -> 0 | M5: 0 | N5: Nardo
A6: TU / Betonboor Nardo | B6: 04-12-17 | C6: 481 | D6: 0 | E6: 0.2 | F6: 481 | G6: 0 | I6: 0 | J6: =C6+H6 -> 481 | K6: =F6+I6 -> 481 | L6: =J6-K6 -> 0 | M6: 0 | N6: Nardo
A7: Industrie aanhanger enkele besturing | B7: 31-05-18 | C7: 607 | D7: 0 | E7: 0.2 | F7: 607 | G7: 0 | I7: 0 | J7: =C7+H7 -> 607 | K7: =F7+I7 -> 607 | L7: =J7-K7 -> 0 | M7: 0 | N7: Nardo
A8: Mors Smitt / meetinstrument | B8: 22-06-18 | C8: 894 | D8: 0 | E8: 0.2 | F8: 894 | G8: 0 | I8: 0 | J8: =C8+H8 -> 894 | K8: =F8+I8 -> 894 | L8: =J8-K8 -> 0 | M8: 0 | N8: Nardo
A9: Mors Smitt / Eazy PV tester | B9: 23-07-18 | C9: 1040 | D9: 0 | E9: 0.2 | F9: 1040 | G9: 0 | I9: 0 | J9: =C9+H9 -> 1040 | K9: =F9+I9 -> 1040 | L9: =J9-K9 -> 0 | M9: 0 | N9: Nardo
A10: de Wildt / bouwcontainer (Roodehaan) | B10: 14-12-18 | C10: 1100 | D10: 0 | E10: 0.2 | F10: 1100 | G10: 0 | I10: 0 | J10: =C10+H10 -> 1100 | K10: =F10+I10 -> 1100 | L10: =J10-K10 -> 0 | M10: 0 | N10: Roodehaan
A11: maXact / RTK GNSS Reveiver UNI-GR1 | B11: 08-08-19 | C11: 2995 | D11: 12 | E11: 0.2 | F11: 2995 | G11: 0 | I11: 0 | J11: =C11+H11 -> 2995 | K11: =F11+I11 -> 2995 | L11: =J11-K11 -> 0 | M11: 0 | N11: Nardo
A12: Omega / Fluke 6500-2 Starterskist (apparatentester) | B12: 29-08-19 | C12: 1699 | D12: 12 | E12: 0.2 | F12: 1699 | G12: 0 | I12: 0 | J12: =C12+H12 -> 1699 | K12: =F12+I12 -> 1699 | L12: =J12-K12 -> 0 | M12: 0 | N12: Nardo
A13: Brinkbox / bouwcontainer (Wagenborgen) | B13: 12-09-19 | C13: 1540 | D13: 12 | E13: 0.2 | F13: 1540 | G13: 0 | I13: 0 | J13: =C13+H13 -> 1540 | K13: =F13+I13 -> 1540 | L13: =J13-K13 -> 0 | M13: 0 | N13: Wagenborgen
A14: Brinkbox / zeecontainer ('t Oor Den Haag) | B14: 14-01-20 | C14: 1400 | D14: 12 | E14: 0.2 | F14: 1377 | G14: 23 | I14: 23 | J14: =C14+H14 -> 1400 | K14: =F14+I14 -> 1400 | L14: =J14-K14 -> 0 | M14: 0 | N14: Oor
A15: Brinkbox / zeecontainer (Sunrock westfields) | B15: 27-01-20 | C15: 1460 | D15: 12 | E15: 0.2 | F15: 1436 | G15: 24 | I15: 24 | J15: =C15+H15 -> 1460 | K15: =F15+I15 -> 1460 | L15: =J15-K15 -> 0 | M15: 0 | N15: Westfields
A16: Securo / Flir Vue pro warmte camera tbv Drone met Drone Expert Vue Pro | B16: 07-07-20 | C16: 6159 | D16: 12 | E16: 0.2 | F16: 5544 | G16: 615 | I16: 615 | J16: =C16+H16 -> 6159 | K16: =F16+I16 -> 6159 | L16: =J16-K16 -> 0 | M16: 0 | N16: Nardo / Rob v. Mourik
... A28: DJI Mini 2 Fly More Combo (Drone) | B28: 06-07-22 | C28: 495 | D28: 12 | E28: 0.2 | F28: 248 | G28: 247 | I28: 99 | J28: =C28+H28 -> 495 | K28: =F28+I28 -> 347 | L28: =J28-K28 -> 148 | M28: 0 | N28: Nick van Druten
A29: One Pro iOS warmtebeeld camera | B29: 27-10-22 | C29: 452 | D29: 12 | E29: 0.2 | F29: 195 | G29: 257 | I29: 90 | J29: =C29+H29 -> 452 | K29: =F29+I29 -> 285 | L29: =J29-K29 -> 167 | M29: 0 | N29: Nardo | O29: Datum in PDF afgekapt: '27-10-202'
A30: Nieaf-Smitt EazyPV Curve Solar | B30: 01-11-22 | C30: 2099 | D30: 12 | E30: 0.2 | F30: 910 | G30: 1189 | I30: 420 | J30: =C30+H30 -> 2099 | K30: =F30+I30 -> 1330 | L30: =J30-K30 -> 769 | M30: 0 | N30: Nardo
A31: Enlaps - Time laps Camera Tikee 3 Pack | B31: 22-02-23 | C31: 1647 | D31: 12 | E31: 0.2 | F31: 604 | G31: 1043 | I31: 329 | J31: =C31+H31 -> 1647 | K31: =F31+I31 -> 933 | L31: =J31-K31 -> 714 | M31: 0 | N31: Nick van Druten
A32: CARU containers / 20ft stand container (Valgenweg) | B32: 26-09-23 | C32: 1543 | D32: 12 | E32: 0.2 | F32: 386 | G32: 1157 | I32: 309 | J32: =C32+H32 -> 1543 | K32: =F32+I32 -> 695 | L32: =J32-K32 -> 848 | M32: 0 | N32: Valgenweg
A33: CARU containers / 20ft stand container (Roodehaan 2A) | B33: 27-12-23 | C33: 1539 | D33: 12 | E33: 0.2 | F33: 334 | G33: 1205 | I33: 308 | J33: =C33+H33 -> 1539 | K33: =F33+I33 -> 642 | L33: =J33-K33 -> 897 | M33: 0 | N33: Groningen / Roodehaan 2A
A34: Isero BV; 1x telescoopladder 4.1m met 80mm treden voor Tijme… | B34: 16-04-24 | C34: 588 | D34: 12 | E34: 0.2 | F34: 88 | G34: 500 | I34: 118 | J34: =C34+H34 -> 588 | K34: =F34+I34 -> 206 | L34: =J34-K34 -> 382 | M34: 0 | N34: Tijmen Bolmeijer
A35: BrinkBox B.V.; 20FT Zeecontainer nieuw, stelling, verlichting o… | B35: 30-04-24 | C35: 3915 | D35: 12 | E35: 0.2 | F35: 587 | G35: 3328 | I35: 783 | J35: =C35+H35 -> 3915 | K35: =F35+I35 -> 1370 | L35: =J35-K35 -> 2545 | M35: 0 | N35: Locatie Vattenfall Echteld
A37: Totaal | C37: =SUM(C5:C35) -> 58472 | F37: =SUM(F5:F35) -> 43668 | G37: =SUM(G5:G35) -> 14804 | H37: =SUM(H5:H35) -> 0 | I37: =SUM(I5:I35) -> 7432 | J37: =SUM(J5:J35) -> 58472 | K37: =SUM(K5:K35) -> 51100 | L37: =SUM(L5:L35) -> 7372 | M37: =SUM(M5:M35) -> 0
A38: Totaal volgens PDF | C38: 58472 | F38: 43668 | G38: 14804 | H38: 0 | I38: 7432 | J38: 58472 | K38: 51100 | L38: 7372 | M38: 0
A39: Verschil (berekend – PDF) | C39: =C37-C38 -> 0 | F39: =F37-F38 -> 0 | G39: =G37-G38 -> 0 | H39: =H37-H38 -> 0 | I39: =I37-I38 -> 0 | J39: =J37-J38 -> 0 | K39: =K37-K38 -> 0 | L39: =L37-L38 -> 0 | M39: =M37-M38 -> 0
A41: Opmerking PDF: 'Deze MVA worden bij een activatransactie verkocht tegen verkoopprijs = marktwaarde'. Locatie = jaarlijkse check (na check 23-10-2023). Grootboek: #4113 afschrijving, #0230/#0231 aanschaf/cum. afschr.
A42: Blauw = overgenomen uit PDF; zwart = formule (ultimo = primo + investering / afschrijving).

Sheet Kantoorinventaris (p29)
A1: Afschrijvingsstaat kantoorinventaris 2025 – Sunprojects BV
A2: Bron: APA Activa Sunprojects (getekend door beiden), pagina 29 — afschrijving 20% per jaar
A4: Omschrijving | B4: Aanschafdatum | C4: Aanschafwaarde primo | D4: Aantal mnd afschr. | E4: Afschr. % | F4: Cum. afschr. primo | G4: Boekwaarde primo | H4: Investering | I4: Desinvest. aanschafwaarde | J4: Desinvest. cum. afschr. | K4: Afschrijving W&V 2025 | L4: Aanschafwaarde ultimo | M4: Cum. afschr. ultimo | N4: Boekwaarde ultimo | O4: Restwaarde | P4: Locatie / opmerking
A5: Overname inventaris SP NV (bureau's, meetapparatuur e.d.) | B5: 31-12-15 | C5: 1000 | D5: 0 | E5: 0.2 | F5: 1000 | G5: 0 | I5: -1000 | J5: -1000 | K5: 0 | L5: =C5+H5+I5 -> 0 | M5: =F5+J5+K5 -> 0 | N5: =L5-M5 -> 0 | O5: 0
A6: Ikea/eettafels/roltafel//tafel/troley | B6: 18-09-17 | C6: 474 | D6: 0 | E6: 0.2 | F6: 474 | G6: 0 | I6: -474 | J6: -474 | K6: 0 | L6: =C6+H6+I6 -> 0 | M6: =F6+J6+K6 -> 0 | N6: =L6-M6 -> 0 | O6: 0
A7: 6 kantoorstoelen | B7: 18-09-17 | C7: 372 | D7: 0 | E7: 0.2 | F7: 372 | G7: 0 | K7: 0 | L7: =C7+H7+I7 -> 372 | M7: =F7+J7+K7 -> 372 | N7: =L7-M7 -> 0 | O7: 0
A8: TV scherm Philips (vergaderzaal) | B8: 05-12-17 | C8: 454 | D8: 0 | E8: 0.2 | F8: 454 | G8: 0 | I8: -454 | J8: -454 | K8: 0 | L8: =C8+H8+I8 -> 0 | M8: =F8+J8+K8 -> 0 | N8: =L8-M8 -> 0 | O8: 0
A9: IKEA / Archiefkast Galant 160x120 | B9: 06-01-18 | C9: 499 | D9: 0 | E9: 0.2 | F9: 499 | G9: 0 | K9: 0 | L9: =C9+H9+I9 -> 499 | M9: =F9+J9+K9 -> 499 | N9: =L9-M9 -> 0 | O9: 0
A10: Aspa Yspo buro/bureaustoel Interstuhl Masja | B10: 20-05-19 | C10: 904 | D10: 0 | E10: 0.2 | F10: 904 | G10: 0 | I10: -904 | J10: -904 | K10: 0 | L10: =C10+H10+I10 -> 0 | M10: =F10+J10+K10 -> 0 | N10: =L10-M10 -> 0 | O10: 0
A11: Ahrend bureau & 3 bureaustoelen | B11: 18-10-19 | C11: 571 | D11: 0 | E11: 0.2 | F11: 571 | G11: 0 | K11: 0 | L11: =C11+H11+I11 -> 571 | M11: =F11+J11+K11 -> 571 | N11: =L11-M11 -> 0 | O11: 0
A12: MobileIron / Bureaumeubels 2e hands niew kantoor | B12: 25-05-20 | C12: 3150 | D12: 8 | E12: 0.2 | F12: 2940 | G12: 210 | I12: -3150 | J12: -3150 | K12: 210 | L12: =C12+H12+I12 -> 0 | M12: =F12+J12+K12 -> 0 | N12: =L12-M12 -> 0 | O12: 0
A13: Mekelenkamp / plantenbakken en planten kantoor | B13: 17-06-20 | C13: 1616 | D13: 8 | E13: 0.2 | F13: 1481 | G13: 135 | I13: -1616 | J13: -1616 | K13: 135 | L13: =C13+H13+I13 -> 0 | M13: =F13+J13+K13 -> 0 | N13: =L13-M13 -> 0 | O13: 0
A14: Eiken vergadertafel Eliza (Design kantoormeub) | B14: 22-06-20 | C14: 939 | D14: 8 | E14: 0.2 | F14: 862 | G14: 77 | I14: -939 | J14: -939 | K14: 77 | L14: =C14+H14+I14 -> 0 | M14: =F14+J14+K14 -> 0 | N14: =L14-M14 -> 0 | O14: 0
A15: 5x Wandsigning type 1 (wandfoto's / wandbekleding) | B15: 19-08-20 | C15: 2200 | D15: 12 | E15: 0.2 | F15: 1943 | G15: 257 | K15: 257 | L15: =C15+H15+I15 -> 2200 | M15: =F15+J15+K15 -> 2200 | N15: =L15-M15 -> 0 | O15: 0
A16: 3x KMA Slinger bureautafels 160x80 cm | B16: 07-10-20 | C16: 630 | D16: 12 | E16: 0.2 | F16: 536 | G16: 94 | K16: 94 | L16: =C16+H16+I16 -> 630 | M16: =F16+J16+K16 -> 630 | N16: =L16-M16 -> 0 | O16: 0
A17: Brains+Bricks / kantoorinrichting wandfoto's ed | B17: 22-03-21 | C17: 770 | D17: 12 | E17: 0.2 | F17: 590 | G17: 180 | K17: 154 | L17: =C17+H17+I17 -> 770 | M17: =F17+J17+K17 -> 744 | N17: =L17-M17 -> 26 | O17: 0
A18: Brains+Bricks / Akoestische wandpanelen | B18: 24-01-22 | C18: 2630 | D18: 12 | E18: 0.2 | F18: 1534 | G18: 1096 | K18: 526 | L18: =C18+H18+I18 -> 2630 | M18: =F18+J18+K18 -> 2060 | N18: =L18-M18 -> 570 | O18: 0
A19: Officecity Kantoormeubelen, Roldeurkast + draaideurkast | B19: 25-02-22 | C19: 703 | D19: 12 | E19: 0.2 | F19: 399 | G19: 304 | K19: 141 | L19: =C19+H19+I19 -> 703 | M19: =F19+J19+K19 -> 540 | N19: =L19-M19 -> 163 | O19: 0
A20: Officecity Kantoormeubelen, 2x bureau Maroon | B20: 01-04-22 | C20: 591 | D20: 12 | E20: 0.2 | F20: 325 | G20: 266 | K20: 118 | L20: =C20+H20+I20 -> 591 | M20: =F20+J20+K20 -> 443 | N20: =L20-M20 -> 148 | O20: 0
A21: Wilbert bureaustoel | B21: 02-11-22 | C21: 460 | D21: 8 | E21: 0.2 | F21: 199 | G21: 261 | I21: -460 | J21: -260 | K21: 61 | L21: =C21+H21+I21 -> 0 | M21: =F21+J21+K21 -> 0 | N21: =L21-M21 -> 0 | O21: 0
A23: Totaal | C23: =SUM(C5:C21) -> 17963 | F23: =SUM(F5:F21) -> 15083 | G23: =SUM(G5:G21) -> 2880 | H23: =SUM(H5:H21) -> 0 | I23: =SUM(I5:I21) -> -8997 | J23: =SUM(J5:J21) -> -8797 | K23: =SUM(K5:K21) -> 1773 | L23: =SUM(L5:L21) -> 8966 | M23: =SUM(M5:M21) -> 8059 | ... O23: =SUM(O5:O21) -> 0
A24: Totaal volgens PDF | C24: 17963 | F24: 15083 | G24: 2880 | H24: 0 | I24: -8997 | J24: -8797 | K24: 1773 | L24: 8966 | M24: 8059 | N24: 907 | O24: 0
A25: Verschil (berekend – PDF) | C25: =C23-C24 -> 0 | F25: =F23-F24 -> 0 | G25: =G23-G24 -> 0 | H25: =H23-H24 -> 0 | I25: =I23-I24 -> 0 | J25: =J23-J24 -> 0 | K25: =K23-K24 -> 0 | L25: =L23-L24 -> 0 | M25: =M23-M24 -> 0 | ... O25: =O23-O24 -> 0
A27: Desinvestering: boekwaarde € 200, verkoopprijs € 2.500, boekwinst € 2.300 (#4195). Op 20-08-2025 verkocht aan illi Engineering voor € 2.500 (grootste deel = niet gekleurd). De resterende MVA gaan mee met een activatransactie.
A28: Afschrijving per kwartaal: te verwerken t/m Q4 € 1.773; verwerkt Q1 € 471,50, Q2 € 471,50, Q3 € 472,00; afschrijving slotkwartaal € 358,00.

Sheet Automatisering (p31)
A1: Afschrijvingsstaat automatiseringsapparatuur 2025 – Sunprojects BV
A2: Bron: APA Activa Sunprojects (getekend door beiden), pagina 31 — afschrijving 20% per jaar
A4: Omschrijving | B4: Aanschafdatum | C4: Aanschafwaarde primo | D4: Aantal mnd afschr. | E4: Afschr. % | F4: Cum. afschr. primo | G4: Boekwaarde primo | H4: Investering | I4: Afschrijving W&V 2025 | J4: Aanschafwaarde ultimo | K4: Cum. afschr. ultimo | L4: Boekwaarde ultimo | M4: Locatie / bij wie | N4: Opmerking
A5: Asus Vivobook laptop voor Nardo | B5: 10-07-17 | C5: 726 | D5: 6 | E5: 0.2 | F5: 726 | G5: 0 | I5: 0 | J5: =C5+H5 -> 726 | K5: =F5+I5 -> 726 | L5: =J5-K5 -> 0 | M5: Nardo Sewalt
A6: Alternate / PC en toebehoren Daniel | B6: 12-01-18 | C6: 2199 | D6: 12 | E6: 0.2 | F6: 2199 | G6: 0 | I6: 0 | J6: =C6+H6 -> 2199 | K6: =F6+I6 -> 2199 | L6: =J6-K6 -> 0 | M6: Daniel Leite
A7: Acer Aspire 5 laptop voor HL (na crash) | B7: 08-02-18 | C7: 582 | D7: 1 | E7: 0.2 | F7: 582 | G7: 0 | I7: 0 | J7: =C7+H7 -> 582 | K7: =F7+I7 -> 582 | L7: =J7-K7 -> 0 | M7: Hans
A8: Alternate / PC en toebehoren Rogier | B8: 04-12-18 | C8: 1146 | D8: 11 | E8: 0.2 | F8: 1146 | G8: 0 | I8: 0 | J8: =C8+H8 -> 1146 | K8: =F8+I8 -> 1146 | L8: =J8-K8 -> 0 | M8: Rogier Bakker
A9: Gen25 / Salesforce CRM inrichten | B9: 18-09-19 | C9: 21600 | D9: 12 | E9: 0.2 | F9: 21600 | G9: 0 | I9: 0 | J9: =C9+H9 -> 21600 | K9: =F9+I9 -> 21600 | L9: =J9-K9 -> 0 | M9: Diverse licenties sales, engineering en inkoop
A10: Coolblue / Lenovo Thinkpad P73 (Bas) | B10: 13-02-20 | C10: 2002 | D10: 1 | E10: 0.2 | F10: 1934 | G10: 68 | I10: 68 | J10: =C10+H10 -> 2002 | K10: =F10+I10 -> 2002 | L10: =J10-K10 -> 0 | M10: Bas Bouwman | N10: slot
A11: Coolblue / Phillips 65PUS6504 (vergaderruimte) | B11: 02-06-20 | C11: 536 | D11: 5 | E11: 0.2 | F11: 491 | G11: 45 | I11: 45 | J11: =C11+H11 -> 536 | K11: =F11+I11 -> 536 | L11: =J11-K11 -> 0 | M11: In gebruik | N11: slot
A12: Coolblue / HP Pavilion 15 15-cs3974nd | B12: 03-06-20 | C12: 820 | D12: 5 | E12: 0.2 | F12: 752 | G12: 68 | I12: 68 | J12: =C12+H12 -> 820 | K12: =F12+I12 -> 820 | L12: =J12-K12 -> 0 | M12: Voorheen Tomàs Tigchelaar / op voorraad voor hergebruik | N12: slot
A13: Coolblue / HP Pavilion 14-dw0975nd | B13: 17-08-20 | C13: 1040 | D13: 7 | E13: 0.2 | F13: 919 | G13: 121 | I13: 121 | J13: =C13+H13 -> 1040 | K13: =F13+I13 -> 1040 | L13: =J13-K13 -> 0 | M13: Timon Berends | N13: slot
A14: Coolblue / Apple iPhone SE 256GB wit | B14: 18-08-20 | C14: 596 | D14: 7 | E14: 0.2 | F14: 526 | G14: 70 | I14: 70 | J14: =C14+H14 -> 596 | K14: =F14+I14 -> 596 | L14: =J14-K14 -> 0 | M14: Voorraad | N14: slot
A15: Coolblue / HP Pavilion 14-fq0977nd | B15: 02-09-20 | C15: 704 | D15: 8 | E15: 0.2 | F15: 611 | G15: 93 | I15: 93 | J15: =C15+H15 -> 704 | K15: =F15+I15 -> 704 | L15: =J15-K15 -> 0 | M15: Timon Berends | N15: slot
A16: Bol.com, HP Pavilion 15.6 inch laptop (Raymond) | B16: 28-09-20 | C16: 495 | D16: 8 | E16: 0.2 | F16: 429 | G16: 66 | I16: 66 | J16: =C16+H16 -> 495 | K16: =F16+I16 -> 495 | L16: =J16-K16 -> 0 | M16: Raymond vd Velde | N16: slot
A17: Coolblue B.V.; 1 HP 15s-fq1967nd laptop | B17: 05-11-20 | C17: 495 | D17: 10 | E17: 0.2 | F17: 413 | G17: 82 | I17: 82 | J17: =C17+H17 -> 495 | K17: =F17+I17 -> 495 | L17: =J17-K17 -> 0 | M17: Op voorraad voor hergebruik | N17: slot
A18: Coolblue / HP Pavilion (Fabiene) | B18: 31-03-21 | C18: 607 | D18: 12 | E18: 0.2 | F18: 464 | G18: 143 | I18: 121 | J18: =C18+H18 -> 607 | K18: =F18+I18 -> 585 | L18: =J18-K18 -> 22 | M18: Priscilla van Assen
A19: Apple iPhone 12 mini 128GB Zwart | B19: 19-08-21 | C19: 641 | D19: 12 | E19: 0.2 | F19: 437 | G19: 204 | I19: 128 | J19: =C19+H19 -> 641 | K19: =F19+I19 -> 565 | L19: =J19-K19 -> 76 | M19: Hans Lambrechts
A20: Apple iPhone 12 mini 128GB Blauw | B20: 20-08-21 | C20: 727 | D20: 12 | E20: 0.2 | F20: 496 | G20: 231 | I20: 145 | J20: =C20+H20 -> 727 | K20: =F20+I20 -> 641 | L20: =J20-K20 -> 86 | M20: Assets
A21: PlatteTV / Philips 65PUS7805 (Assets) | B21: 22-09-21 | C21: 536 | D21: 12 | E21: 0.2 | F21: 357 | G21: 179 | I21: 107 | J21: =C21+H21 -> 536 | K21: =F21+I21 -> 464 | L21: =J21-K21 -> 72 | M21: Nieuwe vergader ruimte assets
A22: Amazon / 5x Philips 23,8 inch monitoren | B22: 22-09-21 | C22: 761 | D22: 12 | E22: 0.2 | F22: 507 | G22: 254 | I22: 152 | J22: =C22+H22 -> 761 | K22: =F22+I22 -> 659 | L22: =J22-K22 -> 102 | M22: 5x monitor diversen
A23: Lenovo Thinkbook 15 | B23: 02-02-22 | C23: 874 | D23: 12 | E23: 0.2 | F23: 510 | G23: 364 | I23: 175 | J23: =C23+H23 -> 874 | K23: =F23+I23 -> 685 | L23: =J23-K23 -> 189 | M23: Voorheen Adrie Korf / op voorraad voor hergebruik
A24: Brics CAD V22 Pro - Single lifetime licentie | B24: 08-03-22 | C24: 1150 | D24: 12 | E24: 0.2 | F24: 652 | G24: 498 | I24: 230 | J24: =C24+H24 -> 1150 | K24: =F24+I24 -> 882 | L24: =J24-K24 -> 268 | M24: CAD software voor Xander | N24: 1 – wordt jaarlijks geupgrade naar nieuwe versie
A25: Brics CAD V22 Pro - 2 lifetime licenties | B25: 14-04-22 | C25: 2300 | D25: 12 | E25: 0.2 | F25: 1265 | G25: 1035 | I25: 460 | J25: =C25+H25 -> 2300 | K25: =F25+I25 -> 1725 | L25: =J25-K25 -> 575 | M25: CAD software voor Adrie & … | N25: 2 – wordt jaarlijks geupgrade naar nieuwe versie
A26: Brics CAD V22 Pro - Single lifetime licentie | B26: 02-05-22 | C26: 1150 | D26: 12 | E26: 0.2 | F26: 594 | G26: 556 | I26: 230 | J26: =C26+H26 -> 1150 | K26: =F26+I26 -> 824 | L26: =J26-K26 -> 326 | M26: CAD software voor Berend … | N26: 1 – wordt jaarlijks geupgrade naar nieuwe versie
A27: Brics CAD V22 Pro - Single lifetime licentie | B27: 18-05-22 | C27: 1150 | D27: 12 | E27: 0.2 | F27: 594 | G27: 556 | I27: 230 | J27: =C27+H27 -> 1150 | K27: =F27+I27 -> 824 | L27: =J27-K27 -> 326 | M27: CAD software voor Paul … | N27: 1 – wordt jaarlijks geupgrade naar nieuwe versie
A28: Brics CAD V22 Pro - Single lifetime licentie | B28: 05-07-22 | C28: 1150 | D28: 12 | E28: 0.2 | F28: 575 | G28: 575 | I28: 230 | J28: =C28+H28 -> 1150 | K28: =F28+I28 -> 805 | L28: =J28-K28 -> 345 | M28: CAD software voor Martijn V… | N28: 1 – wordt jaarlijks geupgrade naar nieuwe versie
A29: BricsCAD Pro V23 | Perpetual (lifetime) 4x licenties | B29: 08-12-22 | C29: 4600 | D29: 12 | E29: 0.2 | F29: 1917 | G29: 2683 | I29: 920 | J29: =C29+H29 -> 4600 | K29: =F29+I29 -> 2837 | L29: =J29-K29 -> 1763 | M29: CAD software Ana / Daniel / 2 vacant
A30: Asus Vivobook 17 X712EA-AU598W | B30: 27-02-23 | C30: 644 | D30: 12 | E30: 0.2 | F30: 247 | G30: 397 | I30: 129 | J30: =C30+H30 -> 644 | K30: =F30+I30 -> 376 | L30: =J30-K30 -> 268 | M30: Martijn van Wijk
A31: 4x Extreme AP305C-1 + Router ed voor Wifi kantoor | B31: 14-04-23 | C31: 4455 | D31: 12 | E31: 0.2 | F31: 1559 | G31: 2896 | I31: 891 | J31: =C31+H31 -> 4455 | K31: =F31+I31 -> 2450 | L31: =J31-K31 -> 2005 | M31: Algemeen/kantoor Uilenstede
A32: Coolblue B.V.; tbv Assets (cf opgave Priscilla): Apple iPad (2022) 10.9 inch 64GB Wifi + 5G Zilver | B32: 11-03-24 | C32: 590 | D32: 12 | E32: 0.2 | F32: 98 | G32: 590 | I32: 118 | J32: =C32+H32 -> 590 | K32: =F32+I32 -> 216 | L32: =J32-K32 -> 374 | M32: tbv Assets | N32: Boekwaarde primo in PDF = aanschafwaarde (590), niet 590 – 98
A33: Intigris B.V., salesforce Field Service Implementation jan en feb 2024 -/- reeds gefactureerd | B33: 15-03-24 | C33: 8850 | D33: 12 | E33: 0.2 | F33: 1475 | G33: 8850 | I33: 1770 | J33: =C33+H33 -> 8850 | K33: =F33+I33 -> 3245 | L33: =J33-K33 -> 5605 | M33: Kantoor | N33: Boekwaarde primo in PDF = aanschafwaarde (8.850), niet 8.850 – 1.475
A34: BlueAi B.V. / 1x BricsCAD Pro V24, Single, Perpetual, incl. 1 year autorenew maintenance t/m 11-12-2024 | B34: 05-04-24 | C34: 1498 | D34: 12 | E34: 0.2 | F34: 225 | G34: 1498 | I34: 300 | J34: =C34+H34 -> 1498 | K34: =F34+I34 -> 525 | L34: =J34-K34 -> 973 | M34: Simi Olatona | N34: Boekwaarde primo in PDF = aanschafwaarde (1.498), niet 1.498 – 225
A35: Apple iPhone 13 512 GB zwart Timon Berend | B35: 31-08-25 | D35: 5 | E35: 0.2 | H35: 478 | I35: 40 | J35: =C35+H35 -> 478 | K35: =F35+I35 -> 40 | L35: =J35-K35 -> 438 | M35: Timon Berends | N35: Investering 2025
A37: Totaal | C37: =SUM(C5:C35) -> 64624 | F37: =SUM(F5:F35) -> 44300 | G37: =SUM(G5:G35) -> 22122 | H37: =SUM(H5:H35) -> 478 | I37: =SUM(I5:I35) -> 6989 | J37: =SUM(J5:J35) -> 65102 | K37: =SUM(K5:K35) -> 51289 | L37: =SUM(L5:L35) -> 13813
A38: Totaal volgens PDF | C38: 64624 | F38: 44300 | G38: 22122 | H38: 478 | I38: 6989 | J38: 65102 | K38: 51289 | L38: 13813
A39: Verschil (berekend – PDF) | C39: =C37-C38 -> 0 | F39: =F37-F38 -> 0 | G39: =G37-G38 -> 0 | H39: =H37-H38 -> 0 | I39: =I37-I38 -> 0 | J39: =J37-J38 -> 0 | K39: =K37-K38 -> 0 | L39: =L37-L38 -> 0
A41: 'slot' = laatste afschrijving. Locatie = jaarlijkse check of dit nog aanwezig is en bij wie (laatste update 23-10-2023). Grootboek: #4114, #0245, #0246.

Sheet Auto's (p28)
A1: Leaseauto's en eigen auto
A2: Bron: APA Activa Sunprojects (getekend door beiden), pagina 28
A4: Afkoopindicatie per 31-12-2025 ex btw | B4: Brandstof | C4: Kenteken | D4: Merk en type | E4: Naam berijder | F4: Ingang contract | G4: Einddatum contract | H4: Leasebedrag p/m | I4: Opmerking
A5: 23398.25 | B5: Hybride | C5: GLV-22-F | D5: Jeep Comp.1.3PHEV 190 Altitude Aut | E5: Nardo Sewalt | F5: 3-8-2024 | G5: 3-8-2029 | H5: 951.25
A6: 29232.19 | B6: Benzine | D6: Volkswagen Polo 1.0 TSI 70kW Life Edition 5d | E6: Poolauto | F6: 17-1-2025 | G6: 16-1-2030 | H6: 575.25
A7: 27297.33 | B7: Hybride | C7: GRG-80-B | D7: Jeep Comp.1.3PHEV 190 Altitude Aut | E7: R. Boerlage | F7: 7-10-2024 | G7: 7-10-2029 | H7: 968.18
A8: 20306.8 | B8: Hybride | C8: GHV-13-G | D8: Kia ProCeed 1.5 T-GDi DCT7 GT-PlusLine | E8: E.J. Eweg | F8: 14-8-2024 | G8: 13-8-2028 | H8: 836.82
A9: 25447.65 | B9: Hybride | C9: Z-919-PZ | D9: Skoda Kodiaq TSI 110 First Ed. Aut | E9: Timon Berends | F9: 7-5-2024 | G9: 7-5-2029 | H9: 818.82 | I9: ja
A10: =SUM(A5:A9) -> 125682.22 | B10: Totaal leaseauto's | H10: =SUM(H5:H9) -> 4150.32
A12: Eigen auto
A13: Aankoopprijs | B13: Brandstof | C13: Kenteken | D13: Merk en type | E13: Naam berijder | F13: Aankoopdatum
A14: 43949.99 | B14: Hybride | C14: R-975-SB | D14: Volvo XC90 | E14: Raymond van der Velde | F14: 08-01-2023

Sheet Voorraad (p30)
A1: Voorraad Sunprojects en overgebleven bij voorgaande projecten
A2: Bron: APA Activa Sunprojects (getekend door beiden), pagina 30 — laatste wijziging december 2025
A4: Categorie | B4: Merk / artikel | C4: Omschrijving | D4: Aantal | E4: Overgebleven bij | F4: Waarde per mt/stuk | G4: Totaal waarde | H4: Markering | I4: Opmerking
A5: Goten | B5: Trayco | C5: Draadgoot voetjes beton | D5: 25 | F5: 4 | G5: 100
A6: Kabel/stekker/mantelbuis | B6: koper DC | C6: rol 1000m dc kabel 4mm2 blauw | D6: 1000 | E6: 2 rollen | F6: 0.47 | G6: 470 | H6: x
A7: Omvormers | B7: APMT-SC-750 | D7: 1 | E7: A4 FASE 2 Haarlemmermeer | F7: 500 | G7: 500 | H7: foto
A8: Panelen | B8: Akcome | C8: Akcome SK8612M(HV)C-450 [1038mm x 2094mm] zwarte rand | E8: retour 445 Van Mossel | F8: 114.75 | G8: 0 | I8: prijs aangepast obv prijs / inkoopfactuur check eind 2023
A9: Panelen | B9: Akcome | C9: Akcome SK8612M(HV)C-455 [1038mm x 2094mm] zwarte rand | E9: retour 445 Van Mossel | F9: 114.39 | G9: 0
A10: Panelen | B10: Akcome | C10: Akcome 545Wp | E10: retour project? | F10: 144.43 | G10: 0 | I10: prijs aangepast obv prijs / inkoopfactuur check eind 2023
A11: Panelen | B11: Canadian Solar | C11: canadian solar 270Wp glas | E11: akzo nobel | F11: 80.03 | G11: 0 | H11: x | I11: prijs aangepast obv prijs / inkoopfactuur check eind 2021
A12: Panelen | B12: Canadian Solar | C12: canadian solar 415 wp | E12: retour van Ikea Haarlem fase 2 | F12: 116.2 | G12: 0
A13: Panelen | B13: Canadian Solar | C13: Canadian Solar 595 wp zilver rand | E13: retour van 428 CTP Ridderkerk? | F13: 169.58 | G13: 0
A14: Panelen | B14: Canadian Solar | C14: Canadian Solar CS6W-550 | E14: Natec panelen over van Dalfsen veld | F14: 127.05 | G14: 0 | I14: Q1-2024 in loods gezet van #394 = aanpassing op project
A15: Panelen | B15: Jinko | C15: Jinko 390 zilver | E15: 1 volle pallet | F15: 81.12 | G15: 0 | H15: x | I15: prijs aangepast obv prijs / inkoopfactuur check eind 2023
A16: Panelen | B16: Jinko | C16: Jinko 550 | E16: retour van 401 HHSK Groenendijk | F16: 160.5 | G16: 0 | I16: prijs aangepast obv prijs / inkoopfactuur check eind 2023
A17: Panelen | B17: Jinko | C17: Jinko 570Wp | E17: retour Theathergarage Nieuwegein | F17: 140 | G17: 0
A18: Panelen | B18: Jinko | C18: Jinko 460Wp | F18: 128.8 | G18: 0 | I18: prijs aangepast obv prijs / inkoopfactuur check eind 2023
A19: Panelen | B19: Kioto Solar | C19: Kioto Solar Sonnenkraft 380Wp | E19: retour van Ikea Delft | F19: 117.5 | G19: 0
A20: Panelen | B20: Longi | C20: longi 380w zilver | F20: 72.96 | G20: 0 | I20: prijs aangepast obv prijs / inkoopfactuur check eind 2023
A21: Panelen | B21: Longi | C21: longi 390w zilver | F21: 97 | G21: 0
A22: Panelen | B22: Longi | C22: longi 450 w zilver | F22: 95 | G22: 0 | H22: x
A23: Panelen | B23: Miasole | C23: mia sole 120w glaspaneel | D23: 29 | F23: 0 | G23: 0 | H23: x | I23: zie in pagina 2 / was dubbel
A24: Panelen | B24: Longi | C24: LR5-72HTH-575
A25: Panelen | B25: Solarwatt | C25: Solarwatt Classics 375 WP | E25: Solarwatt / over van #402 GD Group | F25: 131.81 | G25: 0 | I25: Q1-2024 in loods gezet van #402
A26: Panelen | B26: Sunport | C26: Sunport S-FLEX 6 II [1840 mm x 1040 mm] | E26: retour van 377 Giant | F26: 144 | G26: 0
A27: Panelen | B27: Sunpower | C27: sunpower 335w fullblack | E27: houthavens | F27: 165 | G27: 0 | H27: x
A28: Panelen | B28: Talesun | C28: talesun 265w zilver | E28: ikea | F28: 98.05 | G28: 0 | H28: x
A29: Panelen | B29: Talesun | C29: talesun 270w zilver | F29: 75 | G29: 0 | H29: x
A30: Panelen | B30: Trina solar | C30: trina 345w zilver | E30: schipholtradepark | F30: 46.5 | G30: 0 | H30: x
A31: Panelen | B31: Trina solar | C31: trina 305 zwart | E31: ikea | F31: 75 | G31: 0 | H31: x
A32: Panelen | B32: Trina solar | C32: trina 270 zilver | E32: IKEA duiven | F32: 95 | G32: 0 | H32: x
A33: Panelen | B33: Trina solar | C33: Trina 375 zilver | E33: 12 gereserveerd voor Bas | F33: 139.61 | G33: 0 | H33: x | I33: prijs aangepast obv prijs / inkoopfactuur check eind 2023
A34: Panelen | B34: Trina solar | C34: Trina TSM 450 w zilver | E34: van Bauhaus | F34: 95 | G34: 0 | H34: x
A35: Panelen | B35: Trina | C35: Trina TSM 450Wp | E35: reserve (aangekocht door Hans) | F35: 112.5 | G35: 0
A36: Panelen | B36: Trina solar | C36: Trina Solar TallmaxM TSM-DE17M(II) 450Wp | E36: van 294 Columbusstraat 12 | F36: 91.8 | G36: 0
A37: Panelen | B37: Trina solar | C37: Trina 310Wp zilver | E37: 1 volle pallet nog ingepakt, 15 losse panelen | F37: 78.74 | G37: 0 | H37: x | I37: prijs aangepast obv prijs / inkoopfactuur check eind 2023
A38: Panelen | B38: TW Solar | C38: Tongwei Solar 505Wp | E38: 1147 panelen | F38: 60.6 | G38: 69508.2
A39: Diversen | B39: UPS Sentiel | C39: tbv roode haan spare | D39: 2 | F39: 120 | G39: 240
A40: Diversen | B40: ABB schakelaars | C40: tbv roode haan spare | D40: 7 | F40: 18482 | G40: 18482 | H40: x
A41: Diversen | B41: Ventilatoren | C41: tbv roode haan spare | D41: 5 | F41: 9240 | G41: 9240
...

Sheet Personeel (p32)
A1: Bijlage 5: Geanonimiseerd overzicht van werknemers met functies en arbeidsvoorwaarden
A2: Bron: APA Activa Sunprojects (getekend door beiden), pagina 32
A4: Afdeling | B4: Persnr | C4: In dienst | D4: Functie | E4: Brutosalaris p/m 2025 | F4: Pensioen compens. 2025 | G4: Autokosten vergoeding 2025 | H4: Type contract en arbeidsvoorwaarden 2025 | I4: PT-er basis 2025 | J4: Opmerking | K4: Begroting 2026: aantal maanden | L4: FTE factor | M4: Brutosalaris 2026 | N4: 13e maand / Christmas | O4: Vakantietoeslag / Holiday | P4: Pensioen compens. | Q4: Totaal brutosalaris 2026 | R4: Lease auto / eigendom
A5: General | B5: 70 | D5: Administration Support | E5: 5568.33 | G5: 0 | H5: contract OT | I5: 0.6 | J5: geen verhoging | K5: 11 | L5: 0.6 | M5: 36750.98 | N5: 0 | O5: 2940.08 | Q5: =SUM(M5:P5) -> 39691.06
A6: General | B6: 17 | C6: 1-09-20 | D6: CEO miv 01-01-2025 | E6: 9250 | F6: 0 | G6: 0 | H6: contract OT / MT bonusregeling | I6: 1 | J6: geen verhoging; € 10.000 bonus indien bepaalde netto winst wordt behaald | K6: 12 | L6: 1 | M6: 111000 | N6: 10000 | O6: 8880 | Q6: =SUM(M6:P6) -> 129880 | R6: Opel bus tijdelijk op eigen verzoek
A7: Sales | B7: 19 | C7: 1-10-20 | D7: Accountmanager | E7: 8000 | F7: 0 | G7: 0 | H7: contract OT; retainer bonus (fixed bedrag op basis maandloon) € 16.500 per 1/7; omzetbonus geschat € 10.000 als gerealiseerde omzet > € 5 mio - 10 mio | I7: 1 | J7: verhoging per 1 jan-2023 gehad / daarna fixed | K7: 12 | L7: 1 | M7: 96000 | N7: 26500 | O7: 7680 | Q7: =SUM(M7:P7) -> 130180 | R7: Volvo XC90 R-975-SB met kilometerregistratie; de Volvo is in eigendom
A8: Project managers | B8: 66 | C8: 20-08-24 | D8: Project manager-E | E8: 4000 | H8: contract BT | I8: 1 | J8: in 2025 omzetting contract OT | K8: 12 | L8: 1 | M8: 48000 | N8: 0 | O8: 3840 | Q8: =SUM(M8:P8) -> 51840
A9: Project managers | B9: 57 | C9: 2-01-24 | D9: Project manager-E | E9: 3900 | H9: contract OT | I9: 1 | J9: laatste verhoging 01-11-2024 | K9: 10 | L9: 0.833333 | M9: 32500 | N9: 0 | O9: 2600 | Q9: =SUM(M9:P9) -> 35100
A10: Project managers | B10: 56 | C10: 2-01-24 | D10: Project manager-CM | E10: 4312 | H10: contract OT miv aug-24 + 38 uur/week | I10: 0.95 | J10: laatste verhoging per 1 jan 2025 | K10: 12 | L10: 0.95 | M10: 49156.8 | O10: 3932.54 | Q10: =SUM(M10:P10) -> 53089.34 | R10: Leaseauto Jeep
A11: Project managers | B11: 50 | C11: 22-05-23 | D11: Project manager-CM | E11: 3800 | H11: contract OT | I11: 1 | J11: laatste verhoging per 23 dec 2023 | K11: 12 | L11: 1 | M11: 45600 | O11: 3648 | Q11: =SUM(M11:P11) -> 49248 | R11: Leaseauto Kia Proceed
A12: Assets | B12: 6 | C12: 1-12-18 | D12: Service Technician | E12: 3293.75 | F12: 250 | H12: contract OT | I12: 1 | J12: laatste verhoging miv 01-01-2024 | K12: 12 | L12: 1 | M12: 39525 | N12: 0 | O12: 3162 | P12: 3000 | Q12: =SUM(M12:P12) -> 45687
A13: Assets | B13: 60 | C13: 1-03-24 | D13: Project Engineer | E13: 3850 | H13: contract OT | I13: 1 | K13: 12 | L13: 1 | M13: 46200 | N13: 0 | O13: 3696 | Q13: =SUM(M13:P13) -> 49896
A14: Engineering Porto | B14: 1 | C14: 15-01-18 | D14: Director of Technology | E14: 5206.3 | H14: contract OT / eind 2024 verhoging gehad | I14: 1 | J14: krijgen 13e maand = Christmas allowance | K14: 12 | L14: 1 | M14: 62475.6 | N14: 5206.3 | O14: 5206.3 | Q14: =SUM(M14:P14) -> 72888.2
A15: Engineering Porto | B15: 2 | C15: 6-05-19 | D15: Design Engineer | E15: 2800 | G15: 153 | H15: contract OT | I15: 1 | J15: krijgen 13e maand = Christmas allowance | K15: 12 | L15: 1 | M15: 33600 | N15: 2800 | O15: 2800 | P15: 1836 | Q15: =SUM(M15:P15) -> 41036
A16: Engineering Porto | B16: 3 | C16: 13-01-25 | D16: Design Engineer | E16: 2000 | H16: contract BT 1 jaar | I16: 1 | J16: krijgen 13e maand = Christmas allowance | K16: 11.5 | L16: 0.958333 | M16: 22041.67 | N16: 2000 | O16: 2000 | Q16: =SUM(M16:P16) -> 26041.67
A18: Totaal brutosalaris p/m 2025 | E18: =SUM(E5:E16) -> 55980.38 | F18: PDF: € 55.980,38
A19: Opslag sociale lasten NL | Q19: 0.175
A20: Opslag sociale lasten Portugal | Q20: 0.235
A21: Totaal brutosalaris NL 2026 | Q21: =SUM(Q5:Q13) -> 584611.4
A22: Sociale lasten NL | Q22: =ROUND(Q21*Q19,0) -> 102307
A23: Totaal brutosalaris Portugal 2026 | Q23: =ROUND(SUM(Q14:Q16),0) -> 139966
A24: Sociale lasten Portugal | Q24: =ROUND(Q23*Q20,0) -> 32892
A25: TOTAAL SALARIS EN SOCIALE LASTEN VAST PERSONEEL 2026 | Q25: =ROUND(Q21+Q22+Q23+Q24,0) -> 859776
A26: Vorige begroting 2026 (november): totaal salaris en sociale lasten | Q26: 1182329
A27: Aantal FTE | Q27: =SUM(L5:L16) -> 11.341666
A28: Aantal werknemers (volgens PDF) | Q28: 15
A30: PDF-totalen: NL € 584.611,40; sociale lasten NL € 102.307; Portugal € 139.966; sociale lasten Portugal € 32.892; totaal € 859.776; FTE 11,3; 15 werknemers (12 in de lijst).

Sheet Contracten (p33)
A1: Bijlage 6: Signed contracts and opportunities bij verkoopovereenkomst activa Sunprojects BV
A2: Bron: APA Activa Sunprojects (getekend door beiden), pagina 33 — stand 14-4-2026
A4: Project | B4: Contract value | C4: Margin | D4: Margin % | E4: Start of work | F4: Remarks
A5: Signed contracts
A6: Waterproject Voorne Putten | B6: 487755 | C6: 75000 | D6: =IF(B6=0,0,C6/B6) -> 0.15376572 | E6: Q3-2026 | F6: First payment has been done, installation work to start asap, SDE delay has been granted for August 2026.
A7: Bergen Greentrust, 2 phase installation | B7: 5656848 | C7: 848527 | D7: =IF(B7=0,0,C7/B7) -> 0.14999996 | E7: Q3-2026 | F7: Awaiting an appeal decision by the Raad van State, expectation is positive just as the first decision.
A8: Westfield The Mall of The Netherlands | B8: 396000 | C8: 80000 | D8: =IF(B8=0,0,C8/B8) -> 0.2020202 | E8: Q2-3-2026 | F8: Roof of customer needs to have a fire resistant coating due to insurance reasons. Thereafter, we can start.
A9: Bergen 3 | B9: 1121737 | C9: 307379 | D9: =IF(B9=0,0,C9/B9) -> 0.27402056 | E9: Q2-2026 | F9: Customer is getting the financing, everything else is done. Can we help after the integration?
A10: Gutami Oude Haske | B10: 5000000 | C10: 750000 | D10: =IF(B10=0,0,C10/B10) -> 0.15 | E10: Q3-2026 | F10: Municipality licences are all approved, now final negotiations.
A11: PV ground park Heidehoek (Hans Lambrechts is for 50% co-developer and co-owner) | B11: 1920000 | C11: 380000 | D11: =IF(B11=0,0,C11/B11) -> 0.19791667 | E11: Q2-2026 | F11: Only the BESS license is awaiting. Getting the financing is now going on.
A12: Carports Boreal | B12: 350000 | C12: 70000 | D12: =IF(B12=0,0,C12/B12) -> 0.2 | E12: Q3-2026 | F12: Customer is waiting for final approval of headoffice in England.
A13: Total signed | B13: =SUM(B6:B12) -> 14932340 | C13: =SUM(C6:C12) -> 2510906 | D13: =IF(B13=0,0,C13/B13) -> 0.16815221 | F13: PDF: € 14.932.340 / € 2.510.906 / 16,8%
A15: Realistic projects/quotes in negotiation
A16: MOU of 25 ground projects in The Netherlands signed with NRG2All (backed by Omnes-France); waiting for grid connections, all other licenses obtained
A17: Pink properties, roof project, RFQ answered | B17: 236000 | C17: 50000 | D17: =IF(B17=0,0,C17/B17) -> 0.21186441 | E17: Q2-2026 | F17: Decision in Q1-2026
A18: Total in negotiation | B18: =SUM(B16:B17) -> 236000 | C18: =SUM(C16:C17) -> 50000 | D18: =IF(B18=0,0,C18/B18) -> 0.21186441
A20: Example calculation (Restant Koopprijs)
A21: Restant Koopprijs (voorbeeld) | B21: 1000000
A22: Aandeel Voorne Putten in totaal signed contracts | B22: =B6/B13 -> 0.032664338
A23: Te betalen uit Restant Koopprijs | B23: =B22*B21 -> 32664.338
A24: PDF: 487.755 / 14.932.340 = 3,27%; 3,27% x 1.000.000 = € 32.664,34
A26: Pipeline of projects
A27: Nr / Project | B27: Location | C27: Project type | D27: Approx. size | F27: Opmerkingen
A28: 1 Pavanis | B28: Maasheseweg 85 te Venray | C28: PV, BESS en laadpalen | D28: 700m2?
A29: 2 Dollard | B29: Groningen | C29: PV op land | D29: 550MWp
A30: 3 Google en NRG2All | B30: Blijham - Groningen | C30: PV op land + directe lijn | D30: 35MWp
A31: 4 Claritas | B31: Breskens | C31: BESS voor 2 locaties
A32: 5 NRG2All | B32: Radboud ziekenhuis parkeren en PV
A33: 6 Return BESS projecten | B33: 3 BESS projecten van elk 200MWh | C33: 3*BESS in NL en 2 in Duitsland | D33: >1GWp
A34: 7 2 OH&M projecten van Theia | B34: Rotterdam en Rilland | D34: € 160k fee / year
A35: 8 Oranjeheuvel aanbesteding | B35: Gemeente Rotterdam | C35: PV op land | D35: 20MWp
A36: 9 Emmet Green | B36: Buitenzomerlanden | C36: PV op land | D36: 18MWp
A37: 10 NRG2All | B37: Zonnepark Heumen | C37: PV op land | D37: 12MWp | F37: middels een directe lijn van 4,5 km.
A38: 11 TP Solar | B38: Schiphol 2 projecten | C38: PV op land | D38: 25 en 20MWp
A39: 12 Google Belgium | B39: Dak van Datacenter | C39: PV op dak | D39: 1 MWp
A40: 13 Sunres lead generation | B40: BESS for agricultural sites, 4/week | C40: BESS of 250kWh-2MWh | D40: >50MWh/year
